Exception ignored in: <function Person.__del__ at 0x7f18a056bb80>
Traceback (most recent call last):
  File "/tmp/ipykernel_9822/1901527688.py", line 3, in __del__
ValueError: Something get bump...
